<?xml version="1.0"?>
<robot xmlns:xacro="http://www.ros.org/wiki/xacro" name="boxy">
  
  <material name="grey">
    <color rgba="0.792156862745098 0.819607843137255 0.933333333333333 1" />
  </material>

  <!-- Macro Definition for the Base -->
  <xacro:macro name="base" params="odom with_wheels">
    <link name="base_link">
      <inertial>
        <origin xyz="-0.257082749974343 -0.227847593519202 0.0535404411050965" rpy="0 0 0" />
        <mass value="70.0210745907357" />
        <inertia ixx="9.06122735721955" ixy="0.0933988942518672" ixz="0.665662584048376" iyy="12.5350462868938" iyz="0.00262520723302998" izz="7.44839974564544" />
      </inertial>
      <visual>
        <origin xyz="0 0 0" rpy="0 0 0" />
        <geometry>
          <mesh filename="package://iai_boxy_base_2/meshes/base_without_wheels.stl" />
        </geometry>
        <material name="grey"/>
      </visual>
      <collision>
        <origin xyz="0 0 0" rpy="0 0 0" />
        <geometry>
          <mesh filename="package://iai_boxy_base_2/meshes/base_without_wheels_lowres.stl" />
        </geometry>
      </collision>
    </link>

    <xacro:if value="${with_wheels}">
      <!-- Front Left Wheel -->
      <joint name="wheel_front_left_joint" type="revolute">
        <limit lower="-1000.0" upper="1000.0" effort="200.0" velocity="1.0" />
        <origin xyz="0.13 0.09 -0.06" rpy="0.0 0.0 0.0" />
        <parent link="base_link" />
        <child link="wheel_front_left" />
        <axis xyz="0 1 0" />
      </joint>
      <link name="wheel_front_left">
        <inertial>
          <origin xyz="0 0 0" rpy="0 0 0" />
          <mass value="2.0" />
          <inertia ixx="0.01" ixy="0.0" ixz="0.0" iyy="0.01" iyz="0.0" izz="0.01" />
        </inertial>
        <visual>
          <geometry>
            <mesh filename="package://iai_boxy_base_2/meshes/wheel_front_left.stl" />
          </geometry>
          <material name="grey"/>
        </visual>
        <collision>
          <origin xyz="0 0 0" rpy="${pi/2} 0 0" />
          <geometry>
            <cylinder radius="0.105" length="0.08"/>
          </geometry>
        </collision>
      </link>

      <!-- Back Left Wheel -->
      <joint name="wheel_back_left_joint" type="revolute">
        <limit lower="-1000.0" upper="1000.0" effort="200.0" velocity="1.0" />
        <origin xyz="-0.648 0.09 -0.06" rpy="0.0 0.0 0.0" />
        <parent link="base_link" />
        <child link="wheel_back_left" />
        <axis xyz="0 1 0" />
      </joint>
      <link name="wheel_back_left">
        <inertial>
          <origin xyz="0 0 0" rpy="0 0 0" />
          <mass value="2.0" />
          <inertia ixx="0.01" ixy="0.0" ixz="0.0" iyy="0.01" iyz="0.0" izz="0.01" />
        </inertial>
        <visual>
          <geometry>
            <mesh filename="package://iai_boxy_base_2/meshes/wheel_back_left.stl" />
          </geometry>
          <material name="grey"/>
        </visual>
        <collision>
          <origin xyz="0 0 0" rpy="${pi/2} 0 0" />
          <geometry>
            <cylinder radius="0.105" length="0.08"/>
          </geometry>
        </collision>
      </link>

      <!-- Front Right Wheel -->
      <joint name="wheel_front_right_joint" type="revolute">
        <limit lower="-1000.0" upper="1000.0" effort="200.0" velocity="1.0" />
        <origin xyz="0.13 -0.545 -0.06" rpy="0.0 0.0 0.0" />
        <parent link="base_link" />
        <child link="wheel_front_right" />
        <axis xyz="0 1 0" />
      </joint>
      <link name="wheel_front_right">
        <inertial>
          <origin xyz="0 0 0" rpy="0 0 0" />
          <mass value="2.0" />
          <inertia ixx="0.01" ixy="0.0" ixz="0.0" iyy="0.01" iyz="0.0" izz="0.01" />
        </inertial>
        <visual>
          <geometry>
            <mesh filename="package://iai_boxy_base_2/meshes/wheel_front_right.stl" />
          </geometry>
          <material name="grey"/>
        </visual>
        <collision>
          <origin xyz="0 0 0" rpy="${pi/2} 0 0" />
          <geometry>
            <cylinder radius="0.105" length="0.08"/>
          </geometry>
        </collision>
      </link>

      <!-- Back Right Wheel -->
      <joint name="wheel_back_right_joint" type="revolute">
        <limit lower="-1000.0" upper="1000.0" effort="200.0" velocity="1.0" />
        <origin xyz="-0.648 -0.545 -0.06" rpy="0.0 0.0 0.0" />
        <parent link="base_link" />
        <child link="wheel_back_right" />
        <axis xyz="0 1 0" />
      </joint>
      <link name="wheel_back_right">
        <inertial>
          <origin xyz="0 0 0" rpy="0 0 0" />
          <mass value="2.0" />
          <inertia ixx="0.01" ixy="0.0" ixz="0.0" iyy="0.01" iyz="0.0" izz="0.01" />
        </inertial>
        <visual>
          <geometry>
            <mesh filename="package://iai_boxy_base_2/meshes/wheel_back_right.stl" />
          </geometry>
          <material name="grey"/>
        </visual>
        <collision>
          <origin xyz="0 0 0" rpy="${pi/2} 0 0" />
          <geometry>
            <cylinder radius="0.105" length="0.08"/>
          </geometry>
        </collision>
      </link>

    </xacro:if>

    <!-- Laser Reference Front -->
    <link name="laser_reference_front">
      <visual>
        <geometry>
          <cylinder radius="0.001" length="0.005"/>
        </geometry>
      </visual>
    </link>
    <joint name="laser_reference_front_joint" type="fixed">
      <origin xyz="0.1772 0.060215 0.149929" rpy="0.0 0.0 0.7853975" />
      <parent link="base_link" />
      <child link="laser_reference_front" />
      <axis xyz="0.0 0.0 0.0" />
    </joint>

    <!-- Laser Reference Back -->
    <link name="laser_reference_back">
      <visual>
        <geometry>
          <cylinder radius="0.001" length="0.005"/>
        </geometry>
      </visual>
    </link>
    <joint name="laser_reference_back_joint" type="fixed">
      <origin xyz="-0.69357 -0.506 0.1575" rpy="4.9333E-15 4.5082E-15 -2.3562" />
      <parent link="base_link" />
      <child link="laser_reference_back" />
      <axis xyz="-1 0 0" />
    </joint>

    <xacro:if value="${odom}">
      <link name="odom" />
      <joint name="odom_x_joint" type="prismatic">
        <parent link="odom" />
        <child link="odom_x_frame" />
        <axis xyz="1 0 0" />
        <limit lower="-1000" upper="1000" velocity="1" effort="200" />
      </joint>
      <link name="odom_x_frame" />
      <joint name="odom_y_joint" type="prismatic">
        <parent link="odom_x_frame" />
        <child link="odom_y_frame" />
        <axis xyz="0 1 0" />
        <limit lower="-1000" upper="1000" velocity="1" effort="200" />
      </joint>
      <link name="odom_y_frame" />
      <joint name="odom_z_joint" type="continuous">
        <parent link="odom_y_frame" />
        <child link="base_footprint" />
        <axis xyz="0 0 1" />
        <limit velocity="1" effort="200" />
      </joint>
    </xacro:if>

    <!-- Base Footprint Link and Joint -->
    <link name="base_footprint">
      <visual>
        <origin rpy="0 0 0" xyz="0 0 0" />
        <geometry>
          <box size="0.01 0.01 0.01" />
        </geometry>
        <material name="White" />
      </visual>
    </link>
    <joint name="base_footprint_joint" type="fixed">
      <origin xyz="0.25525 0.225 0.1616" rpy="0 0 0" />
      <parent link="base_footprint" />
      <child link="base_link" />
    </joint>

    <!-- Plate Link and Joint -->
    <link name="plate">
      <visual>
        <origin rpy="0 0 0" xyz="0 0 0" />
        <geometry>
          <box size="0.6 0.553 0.02" />
        </geometry>
        <material name="Grey" />
      </visual>
      <collision>
        <origin rpy="0 0 0" xyz="0 0 0" />
        <geometry>
          <box size="0.6 0.553 0.02" />
        </geometry>
      </collision>
    </link>
    <joint name="plate_joint" type="fixed">
      <origin xyz="-0.300 -0.230 0.460" rpy="0 0 0" />
      <parent link="base_link" />
      <child link="plate" />
    </joint>
    
  </xacro:macro>

  <!-- Instantiate the base macro with parameters -->
  <xacro:base odom="true" with_wheels="true" />

</robot>
