<?xml version="1.0"?>
<robot xmlns:xacro="http://www.ros.org/wiki/xacro" name="torso">

  <!-- Define properties for easy modification -->
  <xacro:property name="torso_mass" value="3.82694041846288"/>
  <xacro:property name="torso_ixx" value="0.573902290642399"/>
  <xacro:property name="torso_ixy" value="-2.79383327284778E-16"/>
  <xacro:property name="torso_ixz" value="1.66346332789765E-05"/>
  <xacro:property name="torso_iyy" value="0.338648611077492"/>
  <xacro:property name="torso_iyz" value="-1.04080029390922E-16"/>
  <xacro:property name="torso_izz" value="0.239577094605918"/>
  <xacro:property name="triangle_mass" value="7.36699467665114"/>
  <xacro:property name="triangle_ixx" value="0.145376830313475"/>
  <xacro:property name="triangle_ixy" value="0.00013303151578814"/>
  <xacro:property name="triangle_ixz" value="4.5364480793564E-05"/>
  <xacro:property name="triangle_iyy" value="0.280518816650801"/>
  <xacro:property name="triangle_iyz" value="-0.00910948982082533"/>
  <xacro:property name="triangle_izz" value="0.330070759835274"/>
  <xacro:property name="color" value="0.792156862745098 0.819607843137255 0.933333333333333 1"/>
  <xacro:property name="grey_color" value="0.5 0.5 0.5 1"/>
  <xacro:property name="mechanicalReduction" value="1.0"/>
  <xacro:property name="velocity_limit" value="0.02"/>
  <xacro:property name="lower_limit" value="-0.586"/>
  <xacro:property name="upper_limit" value="0.0"/>

  <!-- Dummy root link without inertia -->
  <link name="root_link"/>

  <!-- Fixed joint between root_link and torso_base_link -->
  <joint name="root_to_torso_base" type="fixed">
    <parent link="root_link"/>
    <child link="torso_base_link"/>
    <origin xyz="0 0 0" rpy="0 0 0"/>
  </joint>

  <!-- Torso Base Link Definition -->
  <link name="torso_base_link">
    <inertial>
      <origin xyz="0.0307745199844149 -0.285 0.513294719377322" rpy="0 0 0"/>
      <mass value="${torso_mass}"/>
      <inertia ixx="${torso_ixx}" ixy="${torso_ixy}" ixz="${torso_ixz}"
               iyy="${torso_iyy}" iyz="${torso_iyz}" izz="${torso_izz}"/>
    </inertial>
    <visual>
      <origin xyz="0 0 0" rpy="0 0 0"/>
      <geometry>
        <mesh filename="package://iai_boxy_torso/meshes/torso_base_link.stl"/>
      </geometry>
      <material name="">
        <color rgba="${color}"/>
      </material>
    </visual>
    <collision>
      <origin xyz="0 0 0" rpy="0 0 0"/>
      <geometry>
        <mesh filename="package://iai_boxy_torso/meshes/torso_base_link_simple.stl"/>
      </geometry>
    </collision>
  </link>

  <!-- Triangle Base Link -->
  <link name="triangle_base_link">
    <inertial>
      <origin xyz="-0.302419226632933 -0.181352787411384 -0.0325004871109191" rpy="0 0 0"/>
      <mass value="${triangle_mass}"/>
      <inertia ixx="${triangle_ixx}" ixy="${triangle_ixy}" ixz="${triangle_ixz}"
               iyy="${triangle_iyy}" iyz="${triangle_iyz}" izz="${triangle_izz}"/>
    </inertial>
    <visual>
      <origin xyz="0 0 0" rpy="0 0 0"/>
      <geometry>
        <mesh filename="package://iai_boxy_torso/meshes/triangle_base_link.stl"/>
      </geometry>
      <material name="">
        <color rgba="${color}"/>
      </material>
    </visual>
    <collision>
      <origin xyz="0 0 0" rpy="0 0 0"/>
      <geometry>
        <mesh filename="package://iai_boxy_torso/meshes/triangle_base_link.stl"/>
      </geometry>
    </collision>
  </link>

  <!-- Fixed joint between torso_base_link and triangle_base_link -->
  <joint name="torso_to_triangle" type="prismatic">
    <parent link="torso_base_link"/>
    <child link="triangle_base_link"/>
    <origin xyz="0.0786889663592487 0.0986351579738104 0.996332096493862" rpy="0 0 0"/>
    <axis xyz="0 0 1"/>
    <limit lower="${lower_limit}" upper="${upper_limit}" effort="0" velocity="${velocity_limit}"/>
  </joint>

  <!-- Transmission for ROS2 Control -->
  <transmission name="triangle_base_transmission">
    <type>transmission_interface/SimpleTransmission</type>
    <actuator name="triangle_base_motor">
      <hardwareInterface>EffortJointInterface</hardwareInterface>
    </actuator>
    <joint name="torso_to_triangle">
      <hardwareInterface>EffortJointInterface</hardwareInterface>
    </joint>
    <mechanicalReduction>${mechanicalReduction}</mechanicalReduction>
  </transmission>

  <!-- Triangle Left Arm Link and Joint -->
  <link name="triangle_left_arm_link"/>
  <joint name="triangle_left_arm_joint" type="fixed">
    <parent link="triangle_base_link"/>
    <child link="triangle_left_arm_link"/>
    <origin xyz="0.134209 -0.240707 0.181709" rpy="1.046186267441739 0.005429697608281147 3.1340705895651766"/>
  </joint>

  <!-- Triangle Right Arm Link and Joint -->
  <link name="triangle_right_arm_link"/>
  <joint name="triangle_right_arm_joint" type="fixed">
    <parent link="triangle_base_link"/>
    <child link="triangle_right_arm_link"/>
    <origin xyz="0.133262 -0.366684 0.181581" rpy="1.0482088349514576 -0.00542969760828114 -0.0075220640246236"/>
  </joint>

</robot>
